Workbook

Sheet Parametros
A4: Semilla y parametros (S=205)
A5: S | B5: 205
A6: U - Umbral aprobacion gerencial (CLP) | B6: =50000 + 1000*MOD(205,40) -> 55000
A7: D - Plazo de devolucion (dias) | B7: =10 + MOD(205,3)*5 -> 15
A8: d - Tasa de productos dañados | B8: =0.1 + 0.01*MOD(205,10) -> 0.15
A9: V - Volumen mensual (solicitudes) | B9: =200 + 3*MOD(205,100) -> 215
A10: Retiro en tienda (1=si,0=no) | B10: =MOD(205,2) -> 1
A12: Distribucion: dias entre compra y solicitud
A13: Tramo (dias) | B13: %
A14: 0 a 5 (dentro de D) | B14: 0.3
A15: 6 a 10 (dentro de D) | B15: 0.26
A16: 11 a 15 (dentro de D, limite exacto) | B16: 0.18
A17: 16 a 20 (fuera de D) | B17: 0.14
A18: 21 a 30 (fuera de D) | B18: 0.12
A20: Distribucion: monto de la boleta
A21: Tramo (CLP) | B21: %
A22: 20.000 a 60.000 (U cae aqui) | B22: 0.2
A23: limite inferior tramo 1 | B23: 20000
A24: limite superior tramo 1 | B24: 60000
A25: 60.000 a 100.000 | B25: 0.28
A26: 100.000 a 150.000 | B26: 0.24
A27: 150.000 a 250.000 | B27: 0.18
A28: 250.000 a 400.000 | B28: 0.1
A30: Otras probabilidades (dadas en el enunciado)
A31: % rechazo de gerencia (de los que llegan) | B31: 0.08
A32: % reparable (de los productos dañados) | B32: 0.7
A33: % reproceso por discrepancia (de admisibles que llegan a Finanzas) | B33: 0.09
A35: Supuestos de calculo (sin dato empirico en el enunciado)
A36: % retiro en tienda vs courier (SUPUESTO: 50/50) | B36: 0.5
A39: Tarifas (CLP/hora) y costos fijos
A40: Ejecutivo N1 | B40: 6500
A41: Supervisor | B41: 11000
A42: Operario de bodega | B42: 5800
A43: Gerente Comercial | B43: 18000
A44: Analista de Finanzas | B44: 9200
A45: Tecnico de taller | B45: 8400
A46: Andesexpress (CLP por retiro, solo courier) | B46: 4900
A47: Comision pasarela (CLP por transaccion) | B47: 900
A49: Tiempos por actividad (tabla de datos operacionales)
A50: Actividad | B50: Trabajo (min) | C50: Espera (h)
...

Sheet Trazas
A3: # | B3: Traza (camino en el AS-IS) | C3: P(traza) | D3: Trabajo (min) | E3: Espera (h) | F3: Ciclo (h) | G3: Costo (CLP) | H3: P x Ciclo | I3: P x Costo | J3: P x Trabajo(min) | K3: Retiro | L3: Daño | M3: Reproceso | N3: Termino
A4: 1 | B4: Rechazo por plazo (fuera de los D=15 dias) | C4: =Parametros!$B$69 -> 0.26 | D4: =Parametros!$B$51+Parametros!$B$52 -> 20 | E4: =Parametros!$C$51+Parametros!$C$52 -> 6 | F4: =D4/60+E4 -> 6.3333333 | G4: =(Parametros!$B$51/60*Parametros!$B$40)+(Parametros!$B$52/60*Parametros!$B$40) -> 2166.6667 | H4: =C4*F4 -> 1.6466667 | I4: =C4*G4 -> 563.33333 | J4: =C4*D4 -> 5.2 | N4: rechazo por plazo
A5: 2 | B5: Rechazo por gerencia (monto>U y gerencia rechaza 8%) | C5: =Parametros!$B$68*Parametros!$B$71*Parametros!$B$31 -> 0.04884 | D5: =Parametros!$B$51+Parametros!$B$52+Parametros!$B$53+Parametros!$B$54+Parametros!$B$55 -> 39 | E5: =Parametros!$C$51+Parametros!$C$52+Parametros!$C$53+Parametros!$C$54+Parametros!$C$55 -> 106 | F5: =D5/60+E5 -> 106.65 | G5: =(Parametros!$B$51/60*Parametros!$B$40)+(Parametros!$B$52/60*Parametros!$B$40)+(Parametros!$B$53/60*Parametros!$B$40)+(Parametros!$B$54/60*Parametros!$B$40)+(Parametros!$B$55/60*Parametros!$B$43) -> 5758.3333 | H5: =C5*F5 -> 5.208786 | I5: =C5*G5 -> 281.237 | J5: =C5*D5 -> 1.90476 | N5: rechazo desde gerencia
A6: 3 | B6: Exito | monto<=U | retiro en tienda | sin daño | sin reproceso | C6: =Parametros!$B$68*Parametros!$B$72*Parametros!$B$36*Parametros!$B$74*Parametros!$B$77 -> 0.050084125 | D6: =Parametros!$B$51+Parametros!$B$52+Parametros!$B$53+Parametros!$B$56+Parametros!$B$59+Parametros!$B$60+Parametros!$B$61+Parametros!$B$62+Parametros!$B$63 -> 93 | E6: =Parametros!$C$51+Parametros!$C$52+Parametros!$C$53+Parametros!$C$56+Parametros!$C$59+Parametros!$C$60+Parametros!$C$61+Parametros!$C$62+Parametros!$C$63 -> 188 | F6: =D6/60+E6 -> 189.55 | G6: =(Parametros!$B$51/60*Parametros!$B$40)+(Parametros!$B$52/60*Parametros!$B$40)+(Parametros!$B$53/60*Parametros!$B$40)+(Parametros!$B$56/60*Parametros!$B$41)+(Parametros!$B$60/60*Parametros!$B$42)+(Parametros!$B$61/60*Parametros!$B$42)+(Parametros!$B$62/60*Parametros!$B$44)+(Parametros!$B$63/60*Parametros!$B$44)+Parametros!$B$47 -> 12351.667 | H6: =C6*F6 -> 9.4934459 | I6: =C6*G6 -> 618.62242 | J6: =C6*D6 -> 4.6578236 | K6: tienda | L6: sin daño | M6: no | N6: exito
A7: 4 | B7: Exito | monto<=U | retiro en tienda | sin daño | con reproceso (discrepancia 3 sistemas) | C7: =Parametros!$B$68*Parametros!$B$72*Parametros!$B$36*Parametros!$B$74*Parametros!$B$33 -> 0.004953375 | D7: =Parametros!$B$51+Parametros!$B$52+Parametros!$B$53+Parametros!$B$56+Parametros!$B$59+Parametros!$B$60+Parametros!$B$61+Parametros!$B$62+Parametros!$B$65+Parametros!$B$63 -> 130 | E7: =Parametros!$C$51+Parametros!$C$52+Parametros!$C$53+Parametros!$C$56+Parametros!$C$59+Parametros!$C$60+Parametros!$C$61+Parametros!$C$62+Parametros!$C$65+Parametros!$C$63 -> 212 | F7: =D7/60+E7 -> 214.16667 | G7: =(Parametros!$B$51/60*Parametros!$B$40)+(Parametros!$B$52/60*Parametros!$B$40)+(Parametros!$B$53/60*Parametros!$B$40)+(Parametros!$B$56/60*Parametros!$B$41)+(Parametros!$B$60/60*Parametros!$B$42)+(Parametros!$B$61/60*Parametros!$B$42)+(Parametros!$B$62/60*Parametros!$B$44)+(Parametros!$B$63/60*Parametros!$B$44)+(22/60*Parametros!$B$40)+(15/60*Parametros!$B$44)+Parametros!$B$47 -> 17035 | H7: =C7*F7 -> 1.0608478 | I7: =C7*G7 -> 84.380743 | J7: =C7*D7 -> 0.64393875 | K7: tienda | L7: sin daño | M7: si | N7: exito
A8: 5 | B8: Exito | monto<=U | retiro en tienda | reparable (va a taller) | sin reproceso | C8: =Parametros!$B$68*Parametros!$B$72*Parametros!$B$36*Parametros!$B$75*Parametros!$B$77 -> 0.0061868625 | D8: =Parametros!$B$51+Parametros!$B$52+Parametros!$B$53+Parametros!$B$56+Parametros!$B$59+Parametros!$B$60+Parametros!$B$64+Parametros!$B$61+Parametros!$B$62+Parametros!$B$63 -> 158 | E8: =Parametros!$C$51+Parametros!$C$52+Parametros!$C$53+Parametros!$C$56+Parametros!$C$59+Parametros!$C$60+Parametros!$C$64+Parametros!$C$61+Parametros!$C$62+Parametros!$C$63 -> 308 | F8: =D8/60+E8 -> 310.63333 | G8: =(Parametros!$B$51/60*Parametros!$B$40)+(Parametros!$B$52/60*Parametros!$B$40)+(Parametros!$B$53/60*Parametros!$B$40)+(Parametros!$B$56/60*Parametros!$B$41)+(Parametros!$B$60/60*Parametros!$B$42)+(Parametros!$B$64/60*Parametros!$B$45)+(Parametros!$B$61/60*Parametros!$B$42)+(Parametros!$B$62/60*Parametros!$B$44)+(Parametros!$B$63/60*Parametros!$B$44)+Parametros!$B$47 -> 21451.667 | H8: =C8*F8 -> 1.9218457 | I8: =C8*G8 -> 132.71851 | J8: =C8*D8 -> 0.97752427 | K8: tienda | L8: reparable | M8: no | N8: exito
A9: 6 | B9: Exito | monto<=U | retiro en tienda | reparable (va a taller) | con reproceso (discrepancia 3 sistemas) | C9: =Parametros!$B$68*Parametros!$B$72*Parametros!$B$36*Parametros!$B$75*Parametros!$B$33 -> 0.0006118875 | D9: =Parametros!$B$51+Parametros!$B$52+Parametros!$B$53+Parametros!$B$56+Parametros!$B$59+Parametros!$B$60+Parametros!$B$64+Parametros!$B$61+Parametros!$B$62+Parametros!$B$65+Parametros!$B$63 -> 195 | E9: =Parametros!$C$51+Parametros!$C$52+Parametros!$C$53+Parametros!$C$56+Parametros!$C$59+Parametros!$C$60+Parametros!$C$64+Parametros!$C$61+Parametros!$C$62+Parametros!$C$65+Parametros!$C$63 -> 332 | F9: =D9/60+E9 -> 335.25 | G9: =(Parametros!$B$51/60*Parametros!$B$40)+(Parametros!$B$52/60*Parametros!$B$40)+(Parametros!$B$53/60*Parametros!$B$40)+(Parametros!$B$56/60*Parametros!$B$41)+(Parametros!$B$60/60*Parametros!$B$42)+(Parametros!$B$64/60*Parametros!$B$45)+(Parametros!$B$61/60*Parametros!$B$42)+(Parametros!$B$62/60*Parametros!$B$44)+(Parametros!$B$63/60*Parametros!$B$44)+(22/60*Parametros!$B$40)+(15/60*Parametros!$B$44)+Parametros!$B$47 -> 26135 | H9: =C9*F9 -> 0.20513528 | I9: =C9*G9 -> 15.99168 | J9: =C9*D9 -> 0.11931806 | K9: tienda | L9: reparable | M9: si | N9: exito
A10: 7 | B10: Exito | monto<=U | retiro en tienda | se da de baja | sin reproceso | C10: =Parametros!$B$68*Parametros!$B$72*Parametros!$B$36*Parametros!$B$76*Parametros!$B$77 -> 0.0026515125 | D10: =Parametros!$B$51+Parametros!$B$52+Parametros!$B$53+Parametros!$B$56+Parametros!$B$59+Parametros!$B$60+Parametros!$B$61+Parametros!$B$62+Parametros!$B$63 -> 93 | E10: =Parametros!$C$51+Parametros!$C$52+Parametros!$C$53+Parametros!$C$56+Parametros!$C$59+Parametros!$C$60+Parametros!$C$61+Parametros!$C$62+Parametros!$C$63 -> 188 | F10: =D10/60+E10 -> 189.55 | G10: =(Parametros!$B$51/60*Parametros!$B$40)+(Parametros!$B$52/60*Parametros!$B$40)+(Parametros!$B$53/60*Parametros!$B$40)+(Parametros!$B$56/60*Parametros!$B$41)+(Parametros!$B$60/60*Parametros!$B$42)+(Parametros!$B$61/60*Parametros!$B$42)+(Parametros!$B$62/60*Parametros!$B$44)+(Parametros!$B$63/60*Parametros!$B$44)+Parametros!$B$47 -> 12351.667 | H10: =C10*F10 -> 0.50259419 | I10: =C10*G10 -> 32.750599 | J10: =C10*D10 -> 0.24659066 | K10: tienda | L10: baja | M10: no | N10: exito
A11: 8 | B11: Exito | monto<=U | retiro en tienda | se da de baja | con reproceso (discrepancia 3 sistemas) | C11: =Parametros!$B$68*Parametros!$B$72*Parametros!$B$36*Parametros!$B$76*Parametros!$B$33 -> 0.0002622375 | D11: =Parametros!$B$51+Parametros!$B$52+Parametros!$B$53+Parametros!$B$56+Parametros!$B$59+Parametros!$B$60+Parametros!$B$61+Parametros!$B$62+Parametros!$B$65+Parametros!$B$63 -> 130 | E11: =Parametros!$C$51+Parametros!$C$52+Parametros!$C$53+Parametros!$C$56+Parametros!$C$59+Parametros!$C$60+Parametros!$C$61+Parametros!$C$62+Parametros!$C$65+Parametros!$C$63 -> 212 | F11: =D11/60+E11 -> 214.16667 | G11: =(Parametros!$B$51/60*Parametros!$B$40)+(Parametros!$B$52/60*Parametros!$B$40)+(Parametros!$B$53/60*Parametros!$B$40)+(Parametros!$B$56/60*Parametros!$B$41)+(Parametros!$B$60/60*Parametros!$B$42)+(Parametros!$B$61/60*Parametros!$B$42)+(Parametros!$B$62/60*Parametros!$B$44)+(Parametros!$B$63/60*Parametros!$B$44)+(22/60*Parametros!$B$40)+(15/60*Parametros!$B$44)+Parametros!$B$47 -> 17035 | H11: =C11*F11 -> 0.056162531 | I11: =C11*G11 -> 4.4672158 | J11: =C11*D11 -> 0.034090875 | K11: tienda | L11: baja | M11: si | N11: exito
A12: 9 | B12: Exito | monto<=U | courier (Andesexpress) | sin daño | sin reproceso | C12: =Parametros!$B$68*Parametros!$B$72*Parametros!$B$78*Parametros!$B$74*Parametros!$B$77 -> 0.050084125 | D12: =Parametros!$B$51+Parametros!$B$52+Parametros!$B$53+Parametros!$B$56+Parametros!$B$57+Parametros!$B$58+Parametros!$B$59+Parametros!$B$60+Parametros!$B$61+Parametros!$B$62+Parametros!$B$63 -> 108 | E12: =Parametros!$C$51+Parametros!$C$52+Parametros!$C$53+Parametros!$C$56+Parametros!$C$57+Parametros!$C$58+Parametros!$C$59+Parametros!$C$60+Parametros!$C$61+Parametros!$C$62+Parametros!$C$63 -> 260 | F12: =D12/60+E12 -> 261.8 | G12: =(Parametros!$B$51/60*Parametros!$B$40)+(Parametros!$B$52/60*Parametros!$B$40)+(Parametros!$B$53/60*Parametros!$B$40)+(Parametros!$B$56/60*Parametros!$B$41)+(Parametros!$B$57/60*Parametros!$B$40)+(Parametros!$B$60/60*Parametros!$B$42)+(Parametros!$B$61/60*Parametros!$B$42)+(Parametros!$B$62/60*Parametros!$B$44)+(Parametros!$B$63/60*Parametros!$B$44)+Parametros!$B$46+Parametros!$B$47 -> 18876.667 | H12: =C12*F12 -> 13.112024 | I12: =C12*G12 -> 945.42133 | J12: =C12*D12 -> 5.4090855 | K12: courier | L12: sin daño | M12: no | N12: exito
A13: 10 | B13: Exito | monto<=U | courier (Andesexpress) | sin daño | con reproceso (discrepancia 3 sistemas) | C13: =Parametros!$B$68*Parametros!$B$72*Parametros!$B$78*Parametros!$B$74*Parametros!$B$33 -> 0.004953375 | D13: =Parametros!$B$51+Parametros!$B$52+Parametros!$B$53+Parametros!$B$56+Parametros!$B$57+Parametros!$B$58+Parametros!$B$59+Parametros!$B$60+Parametros!$B$61+Parametros!$B$62+Parametros!$B$65+Parametros!$B$63 -> 145 | E13: =Parametros!$C$51+Parametros!$C$52+Parametros!$C$53+Parametros!$C$56+Parametros!$C$57+Parametros!$C$58+Parametros!$C$59+Parametros!$C$60+Parametros!$C$61+Parametros!$C$62+Parametros!$C$65+Parametros!$C$63 -> 284 | F13: =D13/60+E13 -> 286.41667 | G13: =(Parametros!$B$51/60*Parametros!$B$40)+(Parametros!$B$52/60*Parametros!$B$40)+(Parametros!$B$53/60*Parametros!$B$40)+(Parametros!$B$56/60*Parametros!$B$41)+(Parametros!$B$57/60*Parametros!$B$40)+(Parametros!$B$60/60*Parametros!$B$42)+(Parametros!$B$61/60*Parametros!$B$42)+(Parametros!$B$62/60*Parametros!$B$44)+(Parametros!$B$63/60*Parametros!$B$44)+(22/60*Parametros!$B$40)+(15/60*Parametros!$B$44)+Parametros!$B$46+Parametros!$B$47 -> 23560 | H13: =C13*F13 -> 1.4187292 | I13: =C13*G13 -> 116.70151 | J13: =C13*D13 -> 0.71823937 | K13: courier | L13: sin daño | M13: si | N13: exito
A14: 11 | B14: Exito | monto<=U | courier (Andesexpress) | reparable (va a taller) | sin reproceso | C14: =Parametros!$B$68*Parametros!$B$72*Parametros!$B$78*Parametros!$B$75*Parametros!$B$77 -> 0.0061868625 | D14: =Parametros!$B$51+Parametros!$B$52+Parametros!$B$53+Parametros!$B$56+Parametros!$B$57+Parametros!$B$58+Parametros!$B$59+Parametros!$B$60+Parametros!$B$64+Parametros!$B$61+Parametros!$B$62+Parametros!$B$63 -> 173 | E14: =Parametros!$C$51+Parametros!$C$52+Parametros!$C$53+Parametros!$C$56+Parametros!$C$57+Parametros!$C$58+Parametros!$C$59+Parametros!$C$60+Parametros!$C$64+Parametros!$C$61+Parametros!$C$62+Parametros!$C$63 -> 380 | F14: =D14/60+E14 -> 382.88333 | G14: =(Parametros!$B$51/60*Parametros!$B$40)+(Parametros!$B$52/60*Parametros!$B$40)+(Parametros!$B$53/60*Parametros!$B$40)+(Parametros!$B$56/60*Parametros!$B$41)+(Parametros!$B$57/60*Parametros!$B$40)+(Parametros!$B$60/60*Parametros!$B$42)+(Parametros!$B$64/60*Parametros!$B$45)+(Parametros!$B$61/60*Parametros!$B$42)+(Parametros!$B$62/60*Parametros!$B$44)+(Parametros!$B$63/60*Parametros!$B$44)+Parametros!$B$46+Parametros!$B$47 -> 27976.667 | H14: =C14*F14 -> 2.3688465 | I14: =C14*G14 -> 173.08779 | J14: =C14*D14 -> 1.0703272 | K14: courier | L14: reparable | M14: no | N14: exito
A15: 12 | B15: Exito | monto<=U | courier (Andesexpress) | reparable (va a taller) | con reproceso (discrepancia 3 sistemas) | C15: =Parametros!$B$68*Parametros!$B$72*Parametros!$B$78*Parametros!$B$75*Parametros!$B$33 -> 0.0006118875 | D15: =Parametros!$B$51+Parametros!$B$52+Parametros!$B$53+Parametros!$B$56+Parametros!$B$57+Parametros!$B$58+Parametros!$B$59+Parametros!$B$60+Parametros!$B$64+Parametros!$B$61+Parametros!$B$62+Parametros!$B$65+Parametros!$B$63 -> 210 | E15: =Parametros!$C$51+Parametros!$C$52+Parametros!$C$53+Parametros!$C$56+Parametros!$C$57+Parametros!$C$58+Parametros!$C$59+Parametros!$C$60+Parametros!$C$64+Parametros!$C$61+Parametros!$C$62+Parametros!$C$65+Parametros!$C$63 -> 404 | F15: =D15/60+E15 -> 407.5 | G15: =(Parametros!$B$51/60*Parametros!$B$40)+(Parametros!$B$52/60*Parametros!$B$40)+(Parametros!$B$53/60*Parametros!$B$40)+(Parametros!$B$56/60*Parametros!$B$41)+(Parametros!$B$57/60*Parametros!$B$40)+(Parametros!$B$60/60*Parametros!$B$42)+(Parametros!$B$64/60*Parametros!$B$45)+(Parametros!$B$61/60*Parametros!$B$42)+(Parametros!$B$62/60*Parametros!$B$44)+(Parametros!$B$63/60*Parametros!$B$44)+(22/60*Parametros!$B$40)+(15/60*Parametros!$B$44)+Parametros!$B$46+Parametros!$B$47 -> 32660 | H15: =C15*F15 -> 0.24934416 | I15: =C15*G15 -> 19.984246 | J15: =C15*D15 -> 0.12849637 | K15: courier | L15: reparable | M15: si | N15: exito
A16: 13 | B16: Exito | monto<=U | courier (Andesexpress) | se da de baja | sin reproceso | C16: =Parametros!$B$68*Parametros!$B$72*Parametros!$B$78*Parametros!$B$76*Parametros!$B$77 -> 0.0026515125 | D16: =Parametros!$B$51+Parametros!$B$52+Parametros!$B$53+Parametros!$B$56+Parametros!$B$57+Parametros!$B$58+Parametros!$B$59+Parametros!$B$60+Parametros!$B$61+Parametros!$B$62+Parametros!$B$63 -> 108 | E16: =Parametros!$C$51+Parametros!$C$52+Parametros!$C$53+Parametros!$C$56+Parametros!$C$57+Parametros!$C$58+Parametros!$C$59+Parametros!$C$60+Parametros!$C$61+Parametros!$C$62+Parametros!$C$63 -> 260 | F16: =D16/60+E16 -> 261.8 | G16: =(Parametros!$B$51/60*Parametros!$B$40)+(Parametros!$B$52/60*Parametros!$B$40)+(Parametros!$B$53/60*Parametros!$B$40)+(Parametros!$B$56/60*Parametros!$B$41)+(Parametros!$B$57/60*Parametros!$B$40)+(Parametros!$B$60/60*Parametros!$B$42)+(Parametros!$B$61/60*Parametros!$B$42)+(Parametros!$B$62/60*Parametros!$B$44)+(Parametros!$B$63/60*Parametros!$B$44)+Parametros!$B$46+Parametros!$B$47 -> 18876.667 | H16: =C16*F16 -> 0.69416597 | I16: =C16*G16 -> 50.051718 | J16: =C16*D16 -> 0.28636335 | K16: courier | L16: baja | M16: no | N16: exito
A17: 14 | B17: Exito | monto<=U | courier (Andesexpress) | se da de baja | con reproceso (discrepancia 3 sistemas) | C17: =Parametros!$B$68*Parametros!$B$72*Parametros!$B$78*Parametros!$B$76*Parametros!$B$33 -> 0.0002622375 | D17: =Parametros!$B$51+Parametros!$B$52+Parametros!$B$53+Parametros!$B$56+Parametros!$B$57+Parametros!$B$58+Parametros!$B$59+Parametros!$B$60+Parametros!$B$61+Parametros!$B$62+Parametros!$B$65+Parametros!$B$63 -> 145 | E17: =Parametros!$C$51+Parametros!$C$52+Parametros!$C$53+Parametros!$C$56+Parametros!$C$57+Parametros!$C$58+Parametros!$C$59+Parametros!$C$60+Parametros!$C$61+Parametros!$C$62+Parametros!$C$65+Parametros!$C$63 -> 284 | F17: =D17/60+E17 -> 286.41667 | G17: =(Parametros!$B$51/60*Parametros!$B$40)+(Parametros!$B$52/60*Parametros!$B$40)+(Parametros!$B$53/60*Parametros!$B$40)+(Parametros!$B$56/60*Parametros!$B$41)+(Parametros!$B$57/60*Parametros!$B$40)+(Parametros!$B$60/60*Parametros!$B$42)+(Parametros!$B$61/60*Parametros!$B$42)+(Parametros!$B$62/60*Parametros!$B$44)+(Parametros!$B$63/60*Parametros!$B$44)+(22/60*Parametros!$B$40)+(15/60*Parametros!$B$44)+Parametros!$B$46+Parametros!$B$47 -> 23560 | H17: =C17*F17 -> 0.075109191 | I17: =C17*G17 -> 6.1783155 | J17: =C17*D17 -> 0.038024437 | K17: courier | L17: baja | M17: si | N17: exito
A18: 15 | B18: Exito | monto>U y gerencia aprueba | retiro en tienda | sin daño | sin reproceso | C18: =Parametros!$B$68*Parametros!$B$71*Parametros!$B$73*Parametros!$B$36*Parametros!$B$74*Parametros!$B$77 -> 0.21722201 | D18: =Parametros!$B$51+Parametros!$B$52+Parametros!$B$53+Parametros!$B$54+Parametros!$B$55+Parametros!$B$56+Parametros!$B$59+Parametros!$B$60+Parametros!$B$61+Parametros!$B$62+Parametros!$B$63 -> 107 | E18: =Parametros!$C$51+Parametros!$C$52+Parametros!$C$53+Parametros!$C$54+Parametros!$C$55+Parametros!$C$56+Parametros!$C$59+Parametros!$C$60+Parametros!$C$61+Parametros!$C$62+Parametros!$C$63 -> 240 | F18: =D18/60+E18 -> 241.78333 | G18: =(Parametros!$B$51/60*Parametros!$B$40)+(Parametros!$B$52/60*Parametros!$B$40)+(Parametros!$B$53/60*Parametros!$B$40)+(Parametros!$B$54/60*Parametros!$B$40)+(Parametros!$B$55/60*Parametros!$B$43)+(Parametros!$B$56/60*Parametros!$B$41)+(Parametros!$B$60/60*Parametros!$B$42)+(Parametros!$B$61/60*Parametros!$B$42)+(Parametros!$B$62/60*Parametros!$B$44)+(Parametros!$B$63/60*Parametros!$B$44)+Parametros!$B$47 -> 15401.667 | H18: =C18*F18 -> 52.52066 | I18: =C18*G18 -> 3345.5809 | J18: =C18*D18 -> 23.242755 | K18: tienda | L18: sin daño | M18: no | N18: exito
A19: 16 | B19: Exito | monto>U y gerencia aprueba | retiro en tienda | sin daño | con reproceso (discrepancia 3 sistemas) | C19: =Parametros!$B$68*Parametros!$B$71*Parametros!$B$73*Parametros!$B$36*Parametros!$B$74*Parametros!$B$33 -> 0.021483495 | D19: =Parametros!$B$51+Parametros!$B$52+Parametros!$B$53+Parametros!$B$54+Parametros!$B$55+Parametros!$B$56+Parametros!$B$59+Parametros!$B$60+Parametros!$B$61+Parametros!$B$62+Parametros!$B$65+Parametros!$B$63 -> 144 | E19: =Parametros!$C$51+Parametros!$C$52+Parametros!$C$53+Parametros!$C$54+Parametros!$C$55+Parametros!$C$56+Parametros!$C$59+Parametros!$C$60+Parametros!$C$61+Parametros!$C$62+Parametros!$C$65+Parametros!$C$63 -> 264 | F19: =D19/60+E19 -> 266.4 | G19: =(Parametros!$B$51/60*Parametros!$B$40)+(Parametros!$B$52/60*Parametros!$B$40)+(Parametros!$B$53/60*Parametros!$B$40)+(Parametros!$B$54/60*Parametros!$B$40)+(Parametros!$B$55/60*Parametros!$B$43)+(Parametros!$B$56/60*Parametros!$B$41)+(Parametros!$B$60/60*Parametros!$B$42)+(Parametros!$B$61/60*Parametros!$B$42)+(Parametros!$B$62/60*Parametros!$B$44)+(Parametros!$B$63/60*Parametros!$B$44)+(22/60*Parametros!$B$40)+(15/60*Parametros!$B$44)+Parametros!$B$47 -> 20085 | H19: =C19*F19 -> 5.7232031 | I19: =C19*G19 -> 431.496 | J19: =C19*D19 -> 3.0936233 | K19: tienda | L19: sin daño | M19: si | N19: exito
A20: 17 | B20: Exito | monto>U y gerencia aprueba | retiro en tienda | reparable (va a taller) | sin reproceso | C20: =Parametros!$B$68*Parametros!$B$71*Parametros!$B$73*Parametros!$B$36*Parametros!$B$75*Parametros!$B$77 -> 0.026833307 | D20: =Parametros!$B$51+Parametros!$B$52+Parametros!$B$53+Parametros!$B$54+Parametros!$B$55+Parametros!$B$56+Parametros!$B$59+Parametros!$B$60+Parametros!$B$64+Parametros!$B$61+Parametros!$B$62+Parametros!$B$63 -> 172 | E20: =Parametros!$C$51+Parametros!$C$52+Parametros!$C$53+Parametros!$C$54+Parametros!$C$55+Parametros!$C$56+Parametros!$C$59+Parametros!$C$60+Parametros!$C$64+Parametros!$C$61+Parametros!$C$62+Parametros!$C$63 -> 360 | F20: =D20/60+E20 -> 362.86667 | G20: =(Parametros!$B$51/60*Parametros!$B$40)+(Parametros!$B$52/60*Parametros!$B$40)+(Parametros!$B$53/60*Parametros!$B$40)+(Parametros!$B$54/60*Parametros!$B$40)+(Parametros!$B$55/60*Parametros!$B$43)+(Parametros!$B$56/60*Parametros!$B$41)+(Parametros!$B$60/60*Parametros!$B$42)+(Parametros!$B$64/60*Parametros!$B$45)+(Parametros!$B$61/60*Parametros!$B$42)+(Parametros!$B$62/60*Parametros!$B$44)+(Parametros!$B$63/60*Parametros!$B$44)+Parametros!$B$47 -> 24501.667 | H20: =C20*F20 -> 9.7369125 | I20: =C20*G20 -> 657.46073 | J20: =C20*D20 -> 4.6153287 | K20: tienda | L20: reparable | M20: no | N20: exito
A21: 18 | B21: Exito | monto>U y gerencia aprueba | retiro en tienda | reparable (va a taller) | con reproceso (discrepancia 3 sistemas) | C21: =Parametros!$B$68*Parametros!$B$71*Parametros!$B$73*Parametros!$B$36*Parametros!$B$75*Parametros!$B$33 -> 0.0026538435 | D21: =Parametros!$B$51+Parametros!$B$52+Parametros!$B$53+Parametros!$B$54+Parametros!$B$55+Parametros!$B$56+Parametros!$B$59+Parametros!$B$60+Parametros!$B$64+Parametros!$B$61+Parametros!$B$62+Parametros!$B$65+Parametros!$B$63 -> 209 | E21: =Parametros!$C$51+Parametros!$C$52+Parametros!$C$53+Parametros!$C$54+Parametros!$C$55+Parametros!$C$56+Parametros!$C$59+Parametros!$C$60+Parametros!$C$64+Parametros!$C$61+Parametros!$C$62+Parametros!$C$65+Parametros!$C$63 -> 384 | F21: =D21/60+E21 -> 387.48333 | G21: =(Parametros!$B$51/60*Parametros!$B$40)+(Parametros!$B$52/60*Parametros!$B$40)+(Parametros!$B$53/60*Parametros!$B$40)+(Parametros!$B$54/60*Parametros!$B$40)+(Parametros!$B$55/60*Parametros!$B$43)+(Parametros!$B$56/60*Parametros!$B$41)+(Parametros!$B$60/60*Parametros!$B$42)+(Parametros!$B$64/60*Parametros!$B$45)+(Parametros!$B$61/60*Parametros!$B$42)+(Parametros!$B$62/60*Parametros!$B$44)+(Parametros!$B$63/60*Parametros!$B$44)+(22/60*Parametros!$B$40)+(15/60*Parametros!$B$44)+Parametros!$B$47 -> 29185 | H21: =C21*F21 -> 1.0283201 | I21: =C21*G21 -> 77.452423 | J21: =C21*D21 -> 0.55465329 | K21: tienda | L21: reparable | M21: si | N21: exito
A22: 19 | B22: Exito | monto>U y gerencia aprueba | retiro en tienda | se da de baja | sin reproceso | C22: =Parametros!$B$68*Parametros!$B$71*Parametros!$B$73*Parametros!$B$36*Parametros!$B$76*Parametros!$B$77 -> 0.011499989 | D22: =Parametros!$B$51+Parametros!$B$52+Parametros!$B$53+Parametros!$B$54+Parametros!$B$55+Parametros!$B$56+Parametros!$B$59+Parametros!$B$60+Parametros!$B$61+Parametros!$B$62+Parametros!$B$63 -> 107 | E22: =Parametros!$C$51+Parametros!$C$52+Parametros!$C$53+Parametros!$C$54+Parametros!$C$55+Parametros!$C$56+Parametros!$C$59+Parametros!$C$60+Parametros!$C$61+Parametros!$C$62+Parametros!$C$63 -> 240 | F22: =D22/60+E22 -> 241.78333 | G22: =(Parametros!$B$51/60*Parametros!$B$40)+(Parametros!$B$52/60*Parametros!$B$40)+(Parametros!$B$53/60*Parametros!$B$40)+(Parametros!$B$54/60*Parametros!$B$40)+(Parametros!$B$55/60*Parametros!$B$43)+(Parametros!$B$56/60*Parametros!$B$41)+(Parametros!$B$60/60*Parametros!$B$42)+(Parametros!$B$61/60*Parametros!$B$42)+(Parametros!$B$62/60*Parametros!$B$44)+(Parametros!$B$63/60*Parametros!$B$44)+Parametros!$B$47 -> 15401.667 | H22: =C22*F22 -> 2.7805056 | I22: =C22*G22 -> 177.11899 | J22: =C22*D22 -> 1.2304988 | K22: tienda | L22: baja | M22: no | N22: exito
A23: 20 | B23: Exito | monto>U y gerencia aprueba | retiro en tienda | se da de baja | con reproceso (discrepancia 3 sistemas) | C23: =Parametros!$B$68*Parametros!$B$71*Parametros!$B$73*Parametros!$B$36*Parametros!$B$76*Parametros!$B$33 -> 0.0011373615 | D23: =Parametros!$B$51+Parametros!$B$52+Parametros!$B$53+Parametros!$B$54+Parametros!$B$55+Parametros!$B$56+Parametros!$B$59+Parametros!$B$60+Parametros!$B$61+Parametros!$B$62+Parametros!$B$65+Parametros!$B$63 -> 144 | E23: =Parametros!$C$51+Parametros!$C$52+Parametros!$C$53+Parametros!$C$54+Parametros!$C$55+Parametros!$C$56+Parametros!$C$59+Parametros!$C$60+Parametros!$C$61+Parametros!$C$62+Parametros!$C$65+Parametros!$C$63 -> 264 | F23: =D23/60+E23 -> 266.4 | G23: =(Parametros!$B$51/60*Parametros!$B$40)+(Parametros!$B$52/60*Parametros!$B$40)+(Parametros!$B$53/60*Parametros!$B$40)+(Parametros!$B$54/60*Parametros!$B$40)+(Parametros!$B$55/60*Parametros!$B$43)+(Parametros!$B$56/60*Parametros!$B$41)+(Parametros!$B$60/60*Parametros!$B$42)+(Parametros!$B$61/60*Parametros!$B$42)+(Parametros!$B$62/60*Parametros!$B$44)+(Parametros!$B$63/60*Parametros!$B$44)+(22/60*Parametros!$B$40)+(15/60*Parametros!$B$44)+Parametros!$B$47 -> 20085 | H23: =C23*F23 -> 0.3029931 | I23: =C23*G23 -> 22.843906 | J23: =C23*D23 -> 0.16378006 | K23: tienda | L23: baja | M23: si | N23: exito
A24: 21 | B24: Exito | monto>U y gerencia aprueba | courier (Andesexpress) | sin daño | sin reproceso | C24: =Parametros!$B$68*Parametros!$B$71*Parametros!$B$73*Parametros!$B$78*Parametros!$B$74*Parametros!$B$77 -> 0.21722201 | D24: =Parametros!$B$51+Parametros!$B$52+Parametros!$B$53+Parametros!$B$54+Parametros!$B$55+Parametros!$B$56+Parametros!$B$57+Parametros!$B$58+Parametros!$B$59+Parametros!$B$60+Parametros!$B$61+Parametros!$B$62+Parametros!$B$63 -> 122 | E24: =Parametros!$C$51+Parametros!$C$52+Parametros!$C$53+Parametros!$C$54+Parametros!$C$55+Parametros!$C$56+Parametros!$C$57+Parametros!$C$58+Parametros!$C$59+Parametros!$C$60+Parametros!$C$61+Parametros!$C$62+Parametros!$C$63 -> 312 | F24: =D24/60+E24 -> 314.03333 | G24: =(Parametros!$B$51/60*Parametros!$B$40)+(Parametros!$B$52/60*Parametros!$B$40)+(Parametros!$B$53/60*Parametros!$B$40)+(Parametros!$B$54/60*Parametros!$B$40)+(Parametros!$B$55/60*Parametros!$B$43)+(Parametros!$B$56/60*Parametros!$B$41)+(Parametros!$B$57/60*Parametros!$B$40)+(Parametros!$B$60/60*Parametros!$B$42)+(Parametros!$B$61/60*Parametros!$B$42)+(Parametros!$B$62/60*Parametros!$B$44)+(Parametros!$B$63/60*Parametros!$B$44)+Parametros!$B$46+Parametros!$B$47 -> 21926.667 | H24: =C24*F24 -> 68.21495 | I24: =C24*G24 -> 4762.9545 | J24: =C24*D24 -> 26.501085 | K24: courier | L24: sin daño | M24: no | N24: exito
A25: 22 | B25: Exito | monto>U y gerencia aprueba | courier (Andesexpress) | sin daño | con reproceso (discrepancia 3 sistemas) | C25: =Parametros!$B$68*Parametros!$B$71*Parametros!$B$73*Parametros!$B$78*Parametros!$B$74*Parametros!$B$33 -> 0.021483495 | D25: =Parametros!$B$51+Parametros!$B$52+Parametros!$B$53+Parametros!$B$54+Parametros!$B$55+Parametros!$B$56+Parametros!$B$57+Parametros!$B$58+Parametros!$B$59+Parametros!$B$60+Parametros!$B$61+Parametros!$B$62+Parametros!$B$65+Parametros!$B$63 -> 159 | E25: =Parametros!$C$51+Parametros!$C$52+Parametros!$C$53+Parametros!$C$54+Parametros!$C$55+Parametros!$C$56+Parametros!$C$57+Parametros!$C$58+Parametros!$C$59+Parametros!$C$60+Parametros!$C$61+Parametros!$C$62+Parametros!$C$65+Parametros!$C$63 -> 336 | F25: =D25/60+E25 -> 338.65 | G25: =(Parametros!$B$51/60*Parametros!$B$40)+(Parametros!$B$52/60*Parametros!$B$40)+(Parametros!$B$53/60*Parametros!$B$40)+(Parametros!$B$54/60*Parametros!$B$40)+(Parametros!$B$55/60*Parametros!$B$43)+(Parametros!$B$56/60*Parametros!$B$41)+(Parametros!$B$57/60*Parametros!$B$40)+(Parametros!$B$60/60*Parametros!$B$42)+(Parametros!$B$61/60*Parametros!$B$42)+(Parametros!$B$62/60*Parametros!$B$44)+(Parametros!$B$63/60*Parametros!$B$44)+(22/60*Parametros!$B$40)+(15/60*Parametros!$B$44)+Parametros!$B$46+Parametros!$B$47 -> 26610 | H25: =C25*F25 -> 7.2753856 | I25: =C25*G25 -> 571.6758 | J25: =C25*D25 -> 3.4158757 | K25: courier | L25: sin daño | M25: si | N25: exito
A26: 23 | B26: Exito | monto>U y gerencia aprueba | courier (Andesexpress) | reparable (va a taller) | sin reproceso | C26: =Parametros!$B$68*Parametros!$B$71*Parametros!$B$73*Parametros!$B$78*Parametros!$B$75*Parametros!$B$77 -> 0.026833307 | D26: =Parametros!$B$51+Parametros!$B$52+Parametros!$B$53+Parametros!$B$54+Parametros!$B$55+Parametros!$B$56+Parametros!$B$57+Parametros!$B$58+Parametros!$B$59+Parametros!$B$60+Parametros!$B$64+Parametros!$B$61+Parametros!$B$62+Parametros!$B$63 -> 187 | E26: =Parametros!$C$51+Parametros!$C$52+Parametros!$C$53+Parametros!$C$54+Parametros!$C$55+Parametros!$C$56+Parametros!$C$57+Parametros!$C$58+Parametros!$C$59+Parametros!$C$60+Parametros!$C$64+Parametros!$C$61+Parametros!$C$62+Parametros!$C$63 -> 432 | F26: =D26/60+E26 -> 435.11667 | G26: =(Parametros!$B$51/60*Parametros!$B$40)+(Parametros!$B$52/60*Parametros!$B$40)+(Parametros!$B$53/60*Parametros!$B$40)+(Parametros!$B$54/60*Parametros!$B$40)+(Parametros!$B$55/60*Parametros!$B$43)+(Parametros!$B$56/60*Parametros!$B$41)+(Parametros!$B$57/60*Parametros!$B$40)+(Parametros!$B$60/60*Parametros!$B$42)+(Parametros!$B$64/60*Parametros!$B$45)+(Parametros!$B$61/60*Parametros!$B$42)+(Parametros!$B$62/60*Parametros!$B$44)+(Parametros!$B$63/60*Parametros!$B$44)+Parametros!$B$46+Parametros!$B$47 -> 31026.667 | H26: =C26*F26 -> 11.675619 | I26: =C26*G26 -> 832.54806 | J26: =C26*D26 -> 5.0178283 | K26: courier | L26: reparable | M26: no | N26: exito
A27: 24 | B27: Exito | monto>U y gerencia aprueba | courier (Andesexpress) | reparable (va a taller) | con reproceso (discrepancia 3 sistemas) | C27: =Parametros!$B$68*Parametros!$B$71*Parametros!$B$73*Parametros!$B$78*Parametros!$B$75*Parametros!$B$33 -> 0.0026538435 | D27: =Parametros!$B$51+Parametros!$B$52+Parametros!$B$53+Parametros!$B$54+Parametros!$B$55+Parametros!$B$56+Parametros!$B$57+Parametros!$B$58+Parametros!$B$59+Parametros!$B$60+Parametros!$B$64+Parametros!$B$61+Parametros!$B$62+Parametros!$B$65+Parametros!$B$63 -> 224 | E27: =Parametros!$C$51+Parametros!$C$52+Parametros!$C$53+Parametros!$C$54+Parametros!$C$55+Parametros!$C$56+Parametros!$C$57+Parametros!$C$58+Parametros!$C$59+Parametros!$C$60+Parametros!$C$64+Parametros!$C$61+Parametros!$C$62+Parametros!$C$65+Parametros!$C$63 -> 456 | F27: =D27/60+E27 -> 459.73333 | G27: =(Parametros!$B$51/60*Parametros!$B$40)+(Parametros!$B$52/60*Parametros!$B$40)+(Parametros!$B$53/60*Parametros!$B$40)+(Parametros!$B$54/60*Parametros!$B$40)+(Parametros!$B$55/60*Parametros!$B$43)+(Parametros!$B$56/60*Parametros!$B$41)+(Parametros!$B$57/60*Parametros!$B$40)+(Parametros!$B$60/60*Parametros!$B$42)+(Parametros!$B$64/60*Parametros!$B$45)+(Parametros!$B$61/60*Parametros!$B$42)+(Parametros!$B$62/60*Parametros!$B$44)+(Parametros!$B$63/60*Parametros!$B$44)+(22/60*Parametros!$B$40)+(15/60*Parametros!$B$44)+Parametros!$B$46+Parametros!$B$47 -> 35710 | H27: =C27*F27 -> 1.2200603 | I27: =C27*G27 -> 94.768751 | J27: =C27*D27 -> 0.59446094 | K27: courier | L27: reparable | M27: si | N27: exito
A28: 25 | B28: Exito | monto>U y gerencia aprueba | courier (Andesexpress) | se da de baja | sin reproceso | C28: =Parametros!$B$68*Parametros!$B$71*Parametros!$B$73*Parametros!$B$78*Parametros!$B$76*Parametros!$B$77 -> 0.011499989 | D28: =Parametros!$B$51+Parametros!$B$52+Parametros!$B$53+Parametros!$B$54+Parametros!$B$55+Parametros!$B$56+Parametros!$B$57+Parametros!$B$58+Parametros!$B$59+Parametros!$B$60+Parametros!$B$61+Parametros!$B$62+Parametros!$B$63 -> 122 | E28: =Parametros!$C$51+Parametros!$C$52+Parametros!$C$53+Parametros!$C$54+Parametros!$C$55+Parametros!$C$56+Parametros!$C$57+Parametros!$C$58+Parametros!$C$59+Parametros!$C$60+Parametros!$C$61+Parametros!$C$62+Parametros!$C$63 -> 312 | F28: =D28/60+E28 -> 314.03333 | G28: =(Parametros!$B$51/60*Parametros!$B$40)+(Parametros!$B$52/60*Parametros!$B$40)+(Parametros!$B$53/60*Parametros!$B$40)+(Parametros!$B$54/60*Parametros!$B$40)+(Parametros!$B$55/60*Parametros!$B$43)+(Parametros!$B$56/60*Parametros!$B$41)+(Parametros!$B$57/60*Parametros!$B$40)+(Parametros!$B$60/60*Parametros!$B$42)+(Parametros!$B$61/60*Parametros!$B$42)+(Parametros!$B$62/60*Parametros!$B$44)+(Parametros!$B$63/60*Parametros!$B$44)+Parametros!$B$46+Parametros!$B$47 -> 21926.667 | H28: =C28*F28 -> 3.6113797 | I28: =C28*G28 -> 252.15641 | J28: =C28*D28 -> 1.4029986 | K28: courier | L28: baja | M28: no | N28: exito
A29: 26 | B29: Exito | monto>U y gerencia aprueba | courier (Andesexpress) | se da de baja | con reproceso (discrepancia 3 sistemas) | C29: =Parametros!$B$68*Parametros!$B$71*Parametros!$B$73*Parametros!$B$78*Parametros!$B$76*Parametros!$B$33 -> 0.0011373615 | D29: =Parametros!$B$51+Parametros!$B$52+Parametros!$B$53+Parametros!$B$54+Parametros!$B$55+Parametros!$B$56+Parametros!$B$57+Parametros!$B$58+Parametros!$B$59+Parametros!$B$60+Parametros!$B$61+Parametros!$B$62+Parametros!$B$65+Parametros!$B$63 -> 159 | E29: =Parametros!$C$51+Parametros!$C$52+Parametros!$C$53+Parametros!$C$54+Parametros!$C$55+Parametros!$C$56+Parametros!$C$57+Parametros!$C$58+Parametros!$C$59+Parametros!$C$60+Parametros!$C$61+Parametros!$C$62+Parametros!$C$65+Parametros!$C$63 -> 336 | F29: =D29/60+E29 -> 338.65 | G29: =(Parametros!$B$51/60*Parametros!$B$40)+(Parametros!$B$52/60*Parametros!$B$40)+(Parametros!$B$53/60*Parametros!$B$40)+(Parametros!$B$54/60*Parametros!$B$40)+(Parametros!$B$55/60*Parametros!$B$43)+(Parametros!$B$56/60*Parametros!$B$41)+(Parametros!$B$57/60*Parametros!$B$40)+(Parametros!$B$60/60*Parametros!$B$42)+(Parametros!$B$61/60*Parametros!$B$42)+(Parametros!$B$62/60*Parametros!$B$44)+(Parametros!$B$63/60*Parametros!$B$44)+(22/60*Parametros!$B$40)+(15/60*Parametros!$B$44)+Parametros!$B$46+Parametros!$B$47 -> 26610 | H29: =C29*F29 -> 0.38516747 | I29: =C29*G29 -> 30.26519 | J29: =C29*D29 -> 0.18084048 | K29: courier | L29: baja | M29: si | N29: exito
B30: TOTAL / PROMEDIO PONDERADO | C30: =SUM(C4:C29) -> 1 | D30: =SUM(D4:D29) -> 3603 | E30: =SUM(E4:E29) -> 7360 | F30: =SUM(F4:F29) -> 7420.05 | G30: =SUM(G4:G29) -> 548265 | H30: =SUM(H4:H29) -> 202.48886 | I30: =SUM(I4:I29) -> 14301.248 | J30: =SUM(J4:J29) -> 91.44831

Sheet Problemas
A3: # | B3: Problema (tipo) | C3: Evidencia en el AS-IS | D3: Impacto (horas) | E3: Impacto (CLP/mes)
A4: 1 | B4: Control redundante: Rodrigo revalida boleta/plazo que Camila ya verifico | C4: Tareas "Verificar boleta y plazo" (Camila) y "Revisar y autorizar" (Rodrigo) en el AS-IS, lane Atencion al cliente | D4: =(SUMIF(Trazas!$N$4:$N$29,"exito",Trazas!$C$4:$C$29)*Parametros!$B$9)*Parametros!$B$56/60 -> 24.766567 | E4: =(SUMIF(Trazas!$N$4:$N$29,"exito",Trazas!$C$4:$C$29)*Parametros!$B$9)*Parametros!$B$56/60*Parametros!$B$41 -> 272432.23
A5: 2 | B5: Decision tardia: Rodrigo agrupa las revisiones en 2 tandas al dia (loteo) | C5: Espera de 6h asociada a "Revisar y autorizar" (Rodrigo), lane Atencion al cliente | D5: =(SUMIF(Trazas!$N$4:$N$29,"exito",Trazas!$C$4:$C$29)*Parametros!$B$9)*Parametros!$C$56 -> 891.5964 | E5: (no aplica costo directo, es espera que genera horas de ciclo)
A6: 3 | B6: Traspaso manual y reproceso entre 3 sistemas desconectados (planilla, WMS, Finanzas) | C6: Cadena "Digitar en WMS y avisar" luego "Revalidar en Finanzas" (Sebastian revalida lo de Camila/Rodrigo); 9% de discrepancia obliga reproceso | D6: =(SUMIF(Trazas!$N$4:$N$29,"exito",Trazas!$C$4:$C$29)*Parametros!$B$9)*Parametros!$B$62/60 + (SUMIF(Trazas!$M$4:$M$29,"si",Trazas!$C$4:$C$29)*Parametros!$B$9)*Parametros!$B$65/60 -> 30.537177 | E6: =(SUMIF(Trazas!$N$4:$N$29,"exito",Trazas!$C$4:$C$29)*Parametros!$B$9)*Parametros!$B$62/60*Parametros!$B$44 + (SUMIF(Trazas!$M$4:$M$29,"si",Trazas!$C$4:$C$29)*Parametros!$B$9)*(22/60*Parametros!$B$40+15/60*Parametros!$B$44) -> 267701.82
B8: (i) Tiempo de ciclo
B9: Tiempo de ciclo promedio ponderado por probabilidad | C9: =Trazas!H30 -> 202.48886
B10: Tiempo de ciclo promedio ponderado por probabilidad en dias | C10: =C9/24 -> 8.4370358
B11: (ii) Indice de eficiencia del ciclo
B12: Tiempo de trabajo promedio ponderado (h) | C12: =Trazas!J30/60 -> 1.5241385
B13: Indice de eficiencia del ciclo (trabajo/ciclo) | C13: =$C$12/$C$9 -> 0.0075270239
B14: (iii) Costo del proceso
B15: Costo esperado por solicitud recibida (CLP) | C15: =Trazas!I30 -> 14301.248
B16: Costo mensual del proceso (CLP) | C16: =$C$15*Parametros!$B$9 -> 3074768.3
B17: (iv) Volumen mensual por rama (de V=215 solicitudes)
B18: Rama | C18: Solicitudes/mes
B19: Rechazadas por plazo (>D dias) | C19: =Parametros!$B$69*Parametros!$B$9 -> 55.9
B20: Rechazadas por gerencia | C20: =Trazas!C5*Parametros!$B$9 -> 10.5006
B21: Completan el proceso (llegan a reembolso) | C21: =SUM(Trazas!C6:C29)*Parametros!$B$9 -> 148.5994
B22: Por retiro en tienda | C22: =SUMIF(Trazas!$K$4:$K$29,"tienda",Trazas!$C$4:$C$29)*Parametros!$B$9 -> 74.2997
B23: Por courier (Andesexpress) | C23: =SUMIF(Trazas!$K$4:$K$29,"courier",Trazas!$C$4:$C$29)*Parametros!$B$9 -> 74.2997

Sheet Parte C
B2: Cambios TO-BE vs AS-IS (Parte C)
A3: # | B3: Cambio (que cambia respecto al AS-IS) | C3: Principio que lo respalda | D3: Clasificacion | E3: Defensa de la clasificacion | F3: Mejora: horas de ciclo/mes | G3: Mejora: CLP/mes
A4: 1 | B4: Se elimina el paso "Revisar y autorizar" de Rodrigo. Camila queda con autoridad para agendar el retiro directamente (si monto<=U, o apenas gerencia aprueba). | C4: Sesion 3 (ICN-292): "BPR pregunta si el flujo debiera existir". Hammer & Champy (1993): repensar fundamental y redisenar radicalmente el proceso. | D4: Reingenieria | E4: Reingenieria segun la definicion del curso: no se acelera el control, se elimina porque el flujo no deberia existir. Desaparece un paso completo y cambia quien decide (de Rodrigo a Camila): cambia la forma del proceso, no solo su velocidad. | F4: =Problemas!D4+Problemas!D5 -> 916.36297 | G4: =Problemas!E4 -> 272432.23
A5: 2 | B5: Se integra el registro en un solo sistema (planilla+WMS+Finanzas). Desaparece la revalidacion de Sebastian y, con ella, el 9% de reproceso por discrepancia. | C5: Sesion 3 (ICN-292): "Captura unica en origen". Hammer & Champy (1993): repensar fundamentalmente y redisenar radicalmente el proceso. | D5: Reingenieria | E5: Reingenieria: la informacion se captura una sola vez en origen, en lugar de registrarse tres veces y luego reconciliarse. Elimina un paso y una rama entera (el reproceso ya no puede ocurrir); cambia como fluye la informacion, no solo su velocidad. | F5: =(SUMIF(Trazas!$N$4:$N$29,"exito",Trazas!$C$4:$C$29)*Parametros!$B$9)*(Parametros!$B$62/60+Parametros!$C$62)+(SUMIF(Trazas!$M$4:$M$29,"si",Trazas!$C$4:$C$29)*Parametros!$B$9)*(Parametros!$B$65/60+Parametros!$C$65) -> 1243.1083 | G5: =Problemas!E6 -> 267701.82
A6: 3 | B6: Finanzas emite el reembolso todos los dias habiles en vez de un lote semanal los jueves. | C6: Sesion 3 (ICN-292): "Lean/Kaizen mejora incrementalmente" /BPR distinto de mejora continua). No corresponde a un principio de BPR. | D6: Mejora continua | E6: Mejora continua (Lean/Kaizen): el mismo proceso, mas rapido. Mismos pasos, mismo rol decide, misma secuencia; solo se ejecuta con mayor frecuencia. No desaparece nada ni cambia quien decide, por eso no califica como BPR bajo el criterio del curso. | F6: =(SUMIF(Trazas!$N$4:$N$29,"exito",Trazas!$C$4:$C$29)*Parametros!$B$9)*(Parametros!$C$63-'Parte C'!$D$15) -> 10699.157 | G6: 0
A7: 4 | B7: Se digitaliza la ficha de papel de bodega (foto + observaciones) a un formulario en tablet. | C7: Ninguno. Sesion 3 (ICN-292): "No es automatizar lo existente" y "la tecnologia es el habilitador, no el objetivo". | D7: Automatizacion superficial | E7: Automatizacion superficial: se digitaliza un paso sin preguntarse por que existe. No cambia el tiempo de inspeccion (25 min), no conecta con el sistema unificado ni con Finanzas, y no evita el 9% de discrepancia si no se hace tambien el Cambio 2. La tecnologia se usa como objetivo y no como habilitador. | F7: 0 | G7: 0
A8: 5 | B8: La foto del producto pasa a ser un campo obligatorio del formulario web: el cliente la sube al enviar la solicitud, en vez de que Camila se la pida por correo dos dias despues. | C8: Sesion 3 (ICN-292): "Captura unica en origen"; el dato se toma una sola vez, en la fuente (el propio cliente), al inicio del proceso. | D8: Reingenieria | E8: Reingenieria: cambia el orden en que se captura la informacion y quien la entrega (la aporta el propio cliente al inicio). Desaparece una tarea completa y con ella la espera mas larga del tramo inicial. Ademas anula el riesgo del supuesto 1 (que el cliente no responda), porque sin foto la solicitud no se puede enviar. | F8: =Parametros!$B$68*Parametros!$B$9*(Parametros!$C$53+Parametros!$B$53/60) -> 7650.0583 | G8: =Parametros!$B$68*Parametros!$B$9*Parametros!$B$53/60*Parametros!$B$40 -> 86179.167
B10: Parametros de actividad que cambian en el TO-BE
B11: Actividad | C11: AS-IS | D11: TO-BE | E11: Cambio asociado
B12: Revisar y autorizar (Rodrigo) | C12: 10 min trabajo / 6 h espera | D12: Eliminada | E12: Cambio 1
B13: Revalidar en Finanzas (Sebastian) | C13: 9 min trabajo / 6 h espera | D13: Eliminada | E13: Cambio 2
B14: Reproceso por discrepancia entre 3 sistemas | C14: 9% de los casos admisibles, +37 min / +24 h | D14: 0% (ya no puede ocurrir) | E14: Cambio 2
B15: Emitir el reembolso - espera (lote) | C15: 84 h (lote semanal, jueves) | D15: 12 | E15: Cambio 3 (SUPUESTO: lote diario reduce la espera promedio a 12h)
B16: Pedir fotos al cliente | C16: 5 min trabajo / 48 h espera | D16: Eliminada como tarea aparte (la foto llega con la solicitud) | E16: Cambio 5
B18: Arbol de trazas TO-BE (14 combinaciones: sin Rodrigo, sin revalidacion, sin reproceso, lote diario, foto en el formulario inicial)
A19: # | B19: Traza (camino en el TO-BE) | C19: P(traza) | D19: Trabajo (min) | E19: Espera (h) | F19: Ciclo (h) | G19: Costo (CLP) | H19: P x Ciclo | I19: P x Costo | J19: P x Trabajo(min) | K19: Retiro | L19: Daño | M19: Termino
A20: 1 | B20: Rechazo por plazo (fuera de los D=15 dias) | C20: =Parametros!$B$69 -> 0.26 | D20: =Parametros!$B$51+Parametros!$B$52 -> 20 | E20: =Parametros!$C$51+Parametros!$C$52 -> 6 | F20: =D20/60+E20 -> 6.3333333 | G20: =(Parametros!$B$51/60*Parametros!$B$40)+(Parametros!$B$52/60*Parametros!$B$40) -> 2166.6667 | H20: =C20*F20 -> 1.6466667 | I20: =C20*G20 -> 563.33333 | J20: =C20*D20 -> 5.2 | M20: rechazo por plazo
A21: 2 | B21: Rechazo por gerencia (monto>U y gerencia rechaza 8%) | C21: =Parametros!$B$68*Parametros!$B$71*Parametros!$B$31 -> 0.04884 | D21: =Parametros!$B$51+Parametros!$B$52+Parametros!$B$54+Parametros!$B$55 -> 34 | E21: =Parametros!$C$51+Parametros!$C$52+Parametros!$C$54+Parametros!$C$55 -> 58 | F21: =D21/60+E21 -> 58.566667 | G21: =(Parametros!$B$51/60*Parametros!$B$40)+(Parametros!$B$52/60*Parametros!$B$40)+(Parametros!$B$54/60*Parametros!$B$40)+(Parametros!$B$55/60*Parametros!$B$43) -> 5216.6667 | H21: =C21*F21 -> 2.860396 | I21: =C21*G21 -> 254.782 | J21: =C21*D21 -> 1.66056 | M21: rechazo por gerencia
A22: 3 | B22: Exito | monto<=U | retiro en tienda | sin daño | C22: =Parametros!$B$68*Parametros!$B$72*Parametros!$B$36*Parametros!$B$74 -> 0.0550375 | D22: =Parametros!$B$51+Parametros!$B$52+Parametros!$B$59+Parametros!$B$60+Parametros!$B$61+Parametros!$B$63 -> 69 | E22: =Parametros!$C$51+Parametros!$C$52+Parametros!$C$59+Parametros!$C$60+Parametros!$C$61+'Parte C'!$D$15 -> 56 | F22: =D22/60+E22 -> 57.15 | G22: =(Parametros!$B$51/60*Parametros!$B$40)+(Parametros!$B$52/60*Parametros!$B$40)+(Parametros!$B$60/60*Parametros!$B$42)+(Parametros!$B$61/60*Parametros!$B$42)+(Parametros!$B$63/60*Parametros!$B$44)+Parametros!$B$47 -> 8596.6667 | H22: =C22*F22 -> 3.1453931 | I22: =C22*G22 -> 473.13904 | J22: =C22*D22 -> 3.7975875 | K22: tienda | L22: sin daño | M22: exito
A23: 4 | B23: Exito | monto<=U | retiro en tienda | reparable (va a taller) | C23: =Parametros!$B$68*Parametros!$B$72*Parametros!$B$36*Parametros!$B$75 -> 0.00679875 | D23: =Parametros!$B$51+Parametros!$B$52+Parametros!$B$59+Parametros!$B$60+Parametros!$B$64+Parametros!$B$61+Parametros!$B$63 -> 134 | E23: =Parametros!$C$51+Parametros!$C$52+Parametros!$C$59+Parametros!$C$60+Parametros!$C$64+Parametros!$C$61+'Parte C'!$D$15 -> 176 | F23: =D23/60+E23 -> 178.23333 | G23: =(Parametros!$B$51/60*Parametros!$B$40)+(Parametros!$B$52/60*Parametros!$B$40)+(Parametros!$B$60/60*Parametros!$B$42)+(Parametros!$B$64/60*Parametros!$B$45)+(Parametros!$B$61/60*Parametros!$B$42)+(Parametros!$B$63/60*Parametros!$B$44)+Parametros!$B$47 -> 17696.667 | H23: =C23*F23 -> 1.2117639 | I23: =C23*G23 -> 120.31521 | J23: =C23*D23 -> 0.9110325 | K23: tienda | L23: reparable | M23: exito
A24: 5 | B24: Exito | monto<=U | retiro en tienda | se da de baja | C24: =Parametros!$B$68*Parametros!$B$72*Parametros!$B$36*Parametros!$B$76 -> 0.00291375 | D24: =Parametros!$B$51+Parametros!$B$52+Parametros!$B$59+Parametros!$B$60+Parametros!$B$61+Parametros!$B$63 -> 69 | E24: =Parametros!$C$51+Parametros!$C$52+Parametros!$C$59+Parametros!$C$60+Parametros!$C$61+'Parte C'!$D$15 -> 56 | F24: =D24/60+E24 -> 57.15 | G24: =(Parametros!$B$51/60*Parametros!$B$40)+(Parametros!$B$52/60*Parametros!$B$40)+(Parametros!$B$60/60*Parametros!$B$42)+(Parametros!$B$61/60*Parametros!$B$42)+(Parametros!$B$63/60*Parametros!$B$44)+Parametros!$B$47 -> 8596.6667 | H24: =C24*F24 -> 0.16652081 | I24: =C24*G24 -> 25.048538 | J24: =C24*D24 -> 0.20104875 | K24: tienda | L24: baja | M24: exito
A25: 6 | B25: Exito | monto<=U | courier (Andesexpress) | sin daño | C25: =Parametros!$B$68*Parametros!$B$72*Parametros!$B$78*Parametros!$B$74 -> 0.0550375 | D25: =Parametros!$B$51+Parametros!$B$52+Parametros!$B$57+Parametros!$B$58+Parametros!$B$59+Parametros!$B$60+Parametros!$B$61+Parametros!$B$63 -> 84 | E25: =Parametros!$C$51+Parametros!$C$52+Parametros!$C$57+Parametros!$C$58+Parametros!$C$59+Parametros!$C$60+Parametros!$C$61+'Parte C'!$D$15 -> 128 | F25: =D25/60+E25 -> 129.4 | G25: =(Parametros!$B$51/60*Parametros!$B$40)+(Parametros!$B$52/60*Parametros!$B$40)+(Parametros!$B$57/60*Parametros!$B$40)+Parametros!$B$46+(Parametros!$B$60/60*Parametros!$B$42)+(Parametros!$B$61/60*Parametros!$B$42)+(Parametros!$B$63/60*Parametros!$B$44)+Parametros!$B$47 -> 15121.667 | H25: =C25*F25 -> 7.1218525 | I25: =C25*G25 -> 832.25873 | J25: =C25*D25 -> 4.62315 | K25: courier | L25: sin daño | M25: exito
A26: 7 | B26: Exito | monto<=U | courier (Andesexpress) | reparable (va a taller) | C26: =Parametros!$B$68*Parametros!$B$72*Parametros!$B$78*Parametros!$B$75 -> 0.00679875 | D26: =Parametros!$B$51+Parametros!$B$52+Parametros!$B$57+Parametros!$B$58+Parametros!$B$59+Parametros!$B$60+Parametros!$B$64+Parametros!$B$61+Parametros!$B$63 -> 149 | E26: =Parametros!$C$51+Parametros!$C$52+Parametros!$C$57+Parametros!$C$58+Parametros!$C$59+Parametros!$C$60+Parametros!$C$64+Parametros!$C$61+'Parte C'!$D$15 -> 248 | F26: =D26/60+E26 -> 250.48333 | G26: =(Parametros!$B$51/60*Parametros!$B$40)+(Parametros!$B$52/60*Parametros!$B$40)+(Parametros!$B$57/60*Parametros!$B$40)+Parametros!$B$46+(Parametros!$B$60/60*Parametros!$B$42)+(Parametros!$B$64/60*Parametros!$B$45)+(Parametros!$B$61/60*Parametros!$B$42)+(Parametros!$B$63/60*Parametros!$B$44)+Parametros!$B$47 -> 24221.667 | H26: =C26*F26 -> 1.7029736 | I26: =C26*G26 -> 164.67706 | J26: =C26*D26 -> 1.0130137 | K26: courier | L26: reparable | M26: exito
A27: 8 | B27: Exito | monto<=U | courier (Andesexpress) | se da de baja | C27: =Parametros!$B$68*Parametros!$B$72*Parametros!$B$78*Parametros!$B$76 -> 0.00291375 | D27: =Parametros!$B$51+Parametros!$B$52+Parametros!$B$57+Parametros!$B$58+Parametros!$B$59+Parametros!$B$60+Parametros!$B$61+Parametros!$B$63 -> 84 | E27: =Parametros!$C$51+Parametros!$C$52+Parametros!$C$57+Parametros!$C$58+Parametros!$C$59+Parametros!$C$60+Parametros!$C$61+'Parte C'!$D$15 -> 128 | F27: =D27/60+E27 -> 129.4 | G27: =(Parametros!$B$51/60*Parametros!$B$40)+(Parametros!$B$52/60*Parametros!$B$40)+(Parametros!$B$57/60*Parametros!$B$40)+Parametros!$B$46+(Parametros!$B$60/60*Parametros!$B$42)+(Parametros!$B$61/60*Parametros!$B$42)+(Parametros!$B$63/60*Parametros!$B$44)+Parametros!$B$47 -> 15121.667 | H27: =C27*F27 -> 0.37703925 | I27: =C27*G27 -> 44.060756 | J27: =C27*D27 -> 0.244755 | K27: courier | L27: baja | M27: exito
A28: 9 | B28: Exito | monto>U y gerencia aprueba | retiro en tienda | sin daño | C28: =Parametros!$B$68*Parametros!$B$71*Parametros!$B$73*Parametros!$B$36*Parametros!$B$74 -> 0.2387055 | D28: =Parametros!$B$51+Parametros!$B$52+Parametros!$B$54+Parametros!$B$55+Parametros!$B$59+Parametros!$B$60+Parametros!$B$61+Parametros!$B$63 -> 83 | E28: =Parametros!$C$51+Parametros!$C$52+Parametros!$C$54+Parametros!$C$55+Parametros!$C$59+Parametros!$C$60+Parametros!$C$61+'Parte C'!$D$15 -> 108 | F28: =D28/60+E28 -> 109.38333 | G28: =(Parametros!$B$51/60*Parametros!$B$40)+(Parametros!$B$52/60*Parametros!$B$40)+(Parametros!$B$54/60*Parametros!$B$40)+(Parametros!$B$55/60*Parametros!$B$43)+(Parametros!$B$60/60*Parametros!$B$42)+(Parametros!$B$61/60*Parametros!$B$42)+(Parametros!$B$63/60*Parametros!$B$44)+Parametros!$B$47 -> 11646.667 | H28: =C28*F28 -> 26.110403 | I28: =C28*G28 -> 2780.1234 | J28: =C28*D28 -> 19.812556 | K28: tienda | L28: sin daño | M28: exito
A29: 10 | B29: Exito | monto>U y gerencia aprueba | retiro en tienda | reparable (va a taller) | C29: =Parametros!$B$68*Parametros!$B$71*Parametros!$B$73*Parametros!$B$36*Parametros!$B$75 -> 0.02948715 | D29: =Parametros!$B$51+Parametros!$B$52+Parametros!$B$54+Parametros!$B$55+Parametros!$B$59+Parametros!$B$60+Parametros!$B$64+Parametros!$B$61+Parametros!$B$63 -> 148 | E29: =Parametros!$C$51+Parametros!$C$52+Parametros!$C$54+Parametros!$C$55+Parametros!$C$59+Parametros!$C$60+Parametros!$C$64+Parametros!$C$61+'Parte C'!$D$15 -> 228 | F29: =D29/60+E29 -> 230.46667 | G29: =(Parametros!$B$51/60*Parametros!$B$40)+(Parametros!$B$52/60*Parametros!$B$40)+(Parametros!$B$54/60*Parametros!$B$40)+(Parametros!$B$55/60*Parametros!$B$43)+(Parametros!$B$60/60*Parametros!$B$42)+(Parametros!$B$64/60*Parametros!$B$45)+(Parametros!$B$61/60*Parametros!$B$42)+(Parametros!$B$63/60*Parametros!$B$44)+Parametros!$B$47 -> 20746.667 | H29: =C29*F29 -> 6.7958052 | I29: =C29*G29 -> 611.76007 | J29: =C29*D29 -> 4.3640982 | K29: tienda | L29: reparable | M29: exito
A30: 11 | B30: Exito | monto>U y gerencia aprueba | retiro en tienda | se da de baja | C30: =Parametros!$B$68*Parametros!$B$71*Parametros!$B$73*Parametros!$B$36*Parametros!$B$76 -> 0.01263735 | D30: =Parametros!$B$51+Parametros!$B$52+Parametros!$B$54+Parametros!$B$55+Parametros!$B$59+Parametros!$B$60+Parametros!$B$61+Parametros!$B$63 -> 83 | E30: =Parametros!$C$51+Parametros!$C$52+Parametros!$C$54+Parametros!$C$55+Parametros!$C$59+Parametros!$C$60+Parametros!$C$61+'Parte C'!$D$15 -> 108 | F30: =D30/60+E30 -> 109.38333 | G30: =(Parametros!$B$51/60*Parametros!$B$40)+(Parametros!$B$52/60*Parametros!$B$40)+(Parametros!$B$54/60*Parametros!$B$40)+(Parametros!$B$55/60*Parametros!$B$43)+(Parametros!$B$60/60*Parametros!$B$42)+(Parametros!$B$61/60*Parametros!$B$42)+(Parametros!$B$63/60*Parametros!$B$44)+Parametros!$B$47 -> 11646.667 | H30: =C30*F30 -> 1.3823155 | I30: =C30*G30 -> 147.183 | J30: =C30*D30 -> 1.0489001 | K30: tienda | L30: baja | M30: exito
A31: 12 | B31: Exito | monto>U y gerencia aprueba | courier (Andesexpress) | sin daño | C31: =Parametros!$B$68*Parametros!$B$71*Parametros!$B$73*Parametros!$B$78*Parametros!$B$74 -> 0.2387055 | D31: =Parametros!$B$51+Parametros!$B$52+Parametros!$B$54+Parametros!$B$55+Parametros!$B$57+Parametros!$B$58+Parametros!$B$59+Parametros!$B$60+Parametros!$B$61+Parametros!$B$63 -> 98 | E31: =Parametros!$C$51+Parametros!$C$52+Parametros!$C$54+Parametros!$C$55+Parametros!$C$57+Parametros!$C$58+Parametros!$C$59+Parametros!$C$60+Parametros!$C$61+'Parte C'!$D$15 -> 180 | F31: =D31/60+E31 -> 181.63333 | G31: =(Parametros!$B$51/60*Parametros!$B$40)+(Parametros!$B$52/60*Parametros!$B$40)+(Parametros!$B$54/60*Parametros!$B$40)+(Parametros!$B$55/60*Parametros!$B$43)+(Parametros!$B$57/60*Parametros!$B$40)+Parametros!$B$46+(Parametros!$B$60/60*Parametros!$B$42)+(Parametros!$B$61/60*Parametros!$B$42)+(Parametros!$B$63/60*Parametros!$B$44)+Parametros!$B$47 -> 18171.667 | H31: =C31*F31 -> 43.356876 | I31: =C31*G31 -> 4337.6768 | J31: =C31*D31 -> 23.393139 | K31: courier | L31: sin daño | M31: exito
A32: 13 | B32: Exito | monto>U y gerencia aprueba | courier (Andesexpress) | reparable (va a taller) | C32: =Parametros!$B$68*Parametros!$B$71*Parametros!$B$73*Parametros!$B$78*Parametros!$B$75 -> 0.02948715 | D32: =Parametros!$B$51+Parametros!$B$52+Parametros!$B$54+Parametros!$B$55+Parametros!$B$57+Parametros!$B$58+Parametros!$B$59+Parametros!$B$60+Parametros!$B$64+Parametros!$B$61+Parametros!$B$63 -> 163 | E32: =Parametros!$C$51+Parametros!$C$52+Parametros!$C$54+Parametros!$C$55+Parametros!$C$57+Parametros!$C$58+Parametros!$C$59+Parametros!$C$60+Parametros!$C$64+Parametros!$C$61+'Parte C'!$D$15 -> 300 | F32: =D32/60+E32 -> 302.71667 | G32: =(Parametros!$B$51/60*Parametros!$B$40)+(Parametros!$B$52/60*Parametros!$B$40)+(Parametros!$B$54/60*Parametros!$B$40)+(Parametros!$B$55/60*Parametros!$B$43)+(Parametros!$B$57/60*Parametros!$B$40)+Parametros!$B$46+(Parametros!$B$60/60*Parametros!$B$42)+(Parametros!$B$64/60*Parametros!$B$45)+(Parametros!$B$61/60*Parametros!$B$42)+(Parametros!$B$63/60*Parametros!$B$44)+Parametros!$B$47 -> 27271.667 | H32: =C32*F32 -> 8.9262518 | I32: =C32*G32 -> 804.16373 | J32: =C32*D32 -> 4.8064055 | K32: courier | L32: reparable | M32: exito
A33: 14 | B33: Exito | monto>U y gerencia aprueba | courier (Andesexpress) | se da de baja | C33: =Parametros!$B$68*Parametros!$B$71*Parametros!$B$73*Parametros!$B$78*Parametros!$B$76 -> 0.01263735 | D33: =Parametros!$B$51+Parametros!$B$52+Parametros!$B$54+Parametros!$B$55+Parametros!$B$57+Parametros!$B$58+Parametros!$B$59+Parametros!$B$60+Parametros!$B$61+Parametros!$B$63 -> 98 | E33: =Parametros!$C$51+Parametros!$C$52+Parametros!$C$54+Parametros!$C$55+Parametros!$C$57+Parametros!$C$58+Parametros!$C$59+Parametros!$C$60+Parametros!$C$61+'Parte C'!$D$15 -> 180 | F33: =D33/60+E33 -> 181.63333 | G33: =(Parametros!$B$51/60*Parametros!$B$40)+(Parametros!$B$52/60*Parametros!$B$40)+(Parametros!$B$54/60*Parametros!$B$40)+(Parametros!$B$55/60*Parametros!$B$43)+(Parametros!$B$57/60*Parametros!$B$40)+Parametros!$B$46+(Parametros!$B$60/60*Parametros!$B$42)+(Parametros!$B$61/60*Parametros!$B$42)+(Parametros!$B$63/60*Parametros!$B$44)+Parametros!$B$47 -> 18171.667 | H33: =C33*F33 -> 2.295364 | I33: =C33*G33 -> 229.64171 | J33: =C33*D33 -> 1.2384603 | K33: courier | L33: baja | M33: exito
B34: TOTAL / PROMEDIO PONDERADO | C34: =SUM(C20:C33) -> 1 | D34: =SUM(D20:D33) -> 1316 | E34: =SUM(E20:E33) -> 1960 | F34: =SUM(F20:F33) -> 1981.9333 | G34: =SUM(G20:G33) -> 204393.33 | H34: =SUM(H20:H33) -> 107.09962 | I34: =SUM(I20:I33) -> 11388.163 | J34: =SUM(J20:J33) -> 72.314707
B36: Resumen comparativo AS-IS vs TO-BE
B37: Metrica | C37: AS-IS (Parte B) | D37: TO-BE (Parte C) | E37: Mejora
B38: Tiempo de ciclo promedio ponderado (h) | C38: =Problemas!$C$9 -> 202.48886 | D38: ='Parte C'!H34 -> 107.09962 | E38: =1-'Parte C'!H34/Problemas!$C$9 -> 0.47108389
B39: Tiempo de ciclo promedio ponderado por probabilidad en dias | C39: =Problemas!$C$10 -> 8.4370358 | D39: ='Parte C'!H34/24 -> 4.4624842 | E39: =C39-D39 -> 3.9745516
B40: Tiempo de trabajo promedio ponderado (h) | C40: =Problemas!$C$12 -> 1.5241385 | D40: ='Parte C'!J34/60 -> 1.2052451 | E40: =C40-D40 -> 0.31889338
B41: Indice de eficiencia del ciclo | C41: =Problemas!$C$13 -> 0.0075270239 | D41: =('Parte C'!J34/60)/'Parte C'!H34 -> 0.011253496 | E41: =D41-C41 -> 0.0037264717
B42: Costo esperado por solicitud (CLP) | C42: =Problemas!$C$15 -> 14301.248 | D42: ='Parte C'!I34 -> 11388.163 | E42: =Problemas!$C$15-'Parte C'!I34 -> 2913.0847
B43: Costo mensual del proceso (CLP) | C43: =Problemas!$C$16 -> 3074768.3 | D43: ='Parte C'!I34*Parametros!$B$9 -> 2448455.1 | E43: =Problemas!$C$16-'Parte C'!I34*Parametros!$B$9 -> 626313.22
